[2024-05-27T06:54:33.227+0000] {local_task_job_runner.py:120} INFO - ::group::Pre task execution logs
[2024-05-27T06:54:33.251+0000] {taskinstance.py:2076} INFO - Dependencies all met for dep_context=non-requeueable deps ti=<TaskInstance: process_sales.get_send_data_task scheduled__2023-11-25T01:00:00+00:00 [queued]>
[2024-05-27T06:54:33.260+0000] {taskinstance.py:2076} INFO - Dependencies all met for dep_context=requeueable deps ti=<TaskInstance: process_sales.get_send_data_task scheduled__2023-11-25T01:00:00+00:00 [queued]>
[2024-05-27T06:54:33.261+0000] {taskinstance.py:2306} INFO - Starting attempt 1 of 3
[2024-05-27T06:54:33.274+0000] {taskinstance.py:2330} INFO - Executing <Task(PythonOperator): get_send_data_task> on 2023-11-25 01:00:00+00:00
[2024-05-27T06:54:33.287+0000] {warnings.py:110} WARNING - /home/***/.local/lib/python3.12/site-packages/***/task/task_runner/standard_task_runner.py:61: DeprecationWarning: This process (pid=10394) is multi-threaded, use of fork() may lead to deadlocks in the child.
  pid = os.fork()

[2024-05-27T06:54:33.291+0000] {standard_task_runner.py:63} INFO - Started process 10396 to run task
[2024-05-27T06:54:33.290+0000] {standard_task_runner.py:90} INFO - Running: ['***', 'tasks', 'run', 'process_sales', 'get_send_data_task', 'scheduled__2023-11-25T01:00:00+00:00', '--job-id', '1859', '--raw', '--subdir', 'DAGS_FOLDER/process_sales.py', '--cfg-path', '/tmp/tmpkn4thzrh']
[2024-05-27T06:54:33.297+0000] {standard_task_runner.py:91} INFO - Job 1859: Subtask get_send_data_task
[2024-05-27T06:54:33.355+0000] {task_command.py:426} INFO - Running <TaskInstance: process_sales.get_send_data_task scheduled__2023-11-25T01:00:00+00:00 [running]> on host 6ecac41592ab
[2024-05-27T06:54:33.507+0000] {taskinstance.py:2648} INFO - Exporting env vars: AIRFLOW_CTX_DAG_EMAIL='gurlenko.1488@gmail.com' AIRFLOW_CTX_DAG_OWNER='***' AIRFLOW_CTX_DAG_ID='process_sales' AIRFLOW_CTX_TASK_ID='get_send_data_task' AIRFLOW_CTX_EXECUTION_DATE='2023-11-25T01:00:00+00:00' AIRFLOW_CTX_TRY_NUMBER='1' AIRFLOW_CTX_DAG_RUN_ID='scheduled__2023-11-25T01:00:00+00:00'
[2024-05-27T06:54:33.516+0000] {taskinstance.py:430} INFO - ::endgroup::
[2024-05-27T06:54:33.533+0000] {taskinstance.py:441} INFO - ::group::Post task execution logs
[2024-05-27T06:54:33.533+0000] {taskinstance.py:2905} ERROR - Task failed with exception
Traceback (most recent call last):
  File "/home/airflow/.local/lib/python3.12/site-packages/urllib3/connection.py", line 198, in _new_conn
    sock = connection.create_connection(
           ^^^^^^^^^^^^^^^^^^^^^^^^^^^^^
  File "/home/airflow/.local/lib/python3.12/site-packages/urllib3/util/connection.py", line 60, in create_connection
    for res in socket.getaddrinfo(host, port, family, socket.SOCK_STREAM):
               ^^^^^^^^^^^^^^^^^^^^^^^^^^^^^^^^^^^^^^^^^^^^^^^^^^^^^^^^^^
  File "/usr/local/lib/python3.12/socket.py", line 963, in getaddrinfo
    for res in _socket.getaddrinfo(host, port, family, type, proto, flags):
               ^^^^^^^^^^^^^^^^^^^^^^^^^^^^^^^^^^^^^^^^^^^^^^^^^^^^^^^^^^^
socket.gaierror: [Errno -2] Name or service not known

The above exception was the direct cause of the following exception:

Traceback (most recent call last):
  File "/home/airflow/.local/lib/python3.12/site-packages/urllib3/connectionpool.py", line 793, in urlopen
    response = self._make_request(
               ^^^^^^^^^^^^^^^^^^^
  File "/home/airflow/.local/lib/python3.12/site-packages/urllib3/connectionpool.py", line 491, in _make_request
    raise new_e
  File "/home/airflow/.local/lib/python3.12/site-packages/urllib3/connectionpool.py", line 467, in _make_request
    self._validate_conn(conn)
  File "/home/airflow/.local/lib/python3.12/site-packages/urllib3/connectionpool.py", line 1099, in _validate_conn
    conn.connect()
  File "/home/airflow/.local/lib/python3.12/site-packages/urllib3/connection.py", line 616, in connect
    self.sock = sock = self._new_conn()
                       ^^^^^^^^^^^^^^^^
  File "/home/airflow/.local/lib/python3.12/site-packages/urllib3/connection.py", line 205, in _new_conn
    raise NameResolutionError(self.host, self, e) from e
urllib3.exceptions.NameResolutionError: <urllib3.connection.HTTPSConnection object at 0x7f5d7c798ce0>: Failed to resolve 'fake-api-vycpfa6oca-uc.a.run.app' ([Errno -2] Name or service not known)

The above exception was the direct cause of the following exception:

Traceback (most recent call last):
  File "/home/airflow/.local/lib/python3.12/site-packages/requests/adapters.py", line 486, in send
    resp = conn.urlopen(
           ^^^^^^^^^^^^^
  File "/home/airflow/.local/lib/python3.12/site-packages/urllib3/connectionpool.py", line 847, in urlopen
    retries = retries.increment(
              ^^^^^^^^^^^^^^^^^^
  File "/home/airflow/.local/lib/python3.12/site-packages/urllib3/util/retry.py", line 515, in increment
    raise MaxRetryError(_pool, url, reason) from reason  # type: ignore[arg-type]
    ^^^^^^^^^^^^^^^^^^^^^^^^^^^^^^^^^^^^^^^^^^^^^^^^^^^
urllib3.exceptions.MaxRetryError: HTTPSConnectionPool(host='fake-api-vycpfa6oca-uc.a.run.app', port=443): Max retries exceeded with url: /sales?date=2022-08-11&page=1 (Caused by NameResolutionError("<urllib3.connection.HTTPSConnection object at 0x7f5d7c798ce0>: Failed to resolve 'fake-api-vycpfa6oca-uc.a.run.app' ([Errno -2] Name or service not known)"))

During handling of the above exception, another exception occurred:

Traceback (most recent call last):
  File "/home/airflow/.local/lib/python3.12/site-packages/airflow/models/taskinstance.py", line 465, in _execute_task
    result = _execute_callable(context=context, **execute_callable_kwargs)
             ^^^^^^^^^^^^^^^^^^^^^^^^^^^^^^^^^^^^^^^^^^^^^^^^^^^^^^^^^^^^^
  File "/home/airflow/.local/lib/python3.12/site-packages/airflow/models/taskinstance.py", line 432, in _execute_callable
    return execute_callable(context=context, **execute_callable_kwargs)
           ^^^^^^^^^^^^^^^^^^^^^^^^^^^^^^^^^^^^^^^^^^^^^^^^^^^^^^^^^^^^
  File "/home/airflow/.local/lib/python3.12/site-packages/airflow/models/baseoperator.py", line 400, in wrapper
    return func(self, *args, **kwargs)
           ^^^^^^^^^^^^^^^^^^^^^^^^^^^
  File "/home/airflow/.local/lib/python3.12/site-packages/airflow/operators/python.py", line 235, in execute
    return_value = self.execute_callable()
                   ^^^^^^^^^^^^^^^^^^^^^^^
  File "/home/airflow/.local/lib/python3.12/site-packages/airflow/operators/python.py", line 252, in execute_callable
    return self.python_callable(*self.op_args, **self.op_kwargs)
           ^^^^^^^^^^^^^^^^^^^^^^^^^^^^^^^^^^^^^^^^^^^^^^^^^^^^^
  File "/opt/airflow/dags/data_sender.py", line 16, in get_send_data
    data = requests.get(url=API_url,
           ^^^^^^^^^^^^^^^^^^^^^^^^^
  File "/home/airflow/.local/lib/python3.12/site-packages/requests/api.py", line 73, in get
    return request("get", url, params=params, **kwargs)
           ^^^^^^^^^^^^^^^^^^^^^^^^^^^^^^^^^^^^^^^^^^^^
  File "/home/airflow/.local/lib/python3.12/site-packages/requests/api.py", line 59, in request
    return session.request(method=method, url=url, **kwargs)
           ^^^^^^^^^^^^^^^^^^^^^^^^^^^^^^^^^^^^^^^^^^^^^^^^^
  File "/home/airflow/.local/lib/python3.12/site-packages/requests/sessions.py", line 589, in request
    resp = self.send(prep, **send_kwargs)
           ^^^^^^^^^^^^^^^^^^^^^^^^^^^^^^
  File "/home/airflow/.local/lib/python3.12/site-packages/requests/sessions.py", line 703, in send
    r = adapter.send(request, **kwargs)
        ^^^^^^^^^^^^^^^^^^^^^^^^^^^^^^^
  File "/home/airflow/.local/lib/python3.12/site-packages/requests/adapters.py", line 519, in send
    raise ConnectionError(e, request=request)
requests.exceptions.ConnectionError: HTTPSConnectionPool(host='fake-api-vycpfa6oca-uc.a.run.app', port=443): Max retries exceeded with url: /sales?date=2022-08-11&page=1 (Caused by NameResolutionError("<urllib3.connection.HTTPSConnection object at 0x7f5d7c798ce0>: Failed to resolve 'fake-api-vycpfa6oca-uc.a.run.app' ([Errno -2] Name or service not known)"))
[2024-05-27T06:54:33.558+0000] {taskinstance.py:1206} INFO - Marking task as UP_FOR_RETRY. dag_id=process_sales, task_id=get_send_data_task, run_id=scheduled__2023-11-25T01:00:00+00:00, execution_date=20231125T010000, start_date=20240527T065433, end_date=20240527T065433
[2024-05-27T06:54:33.575+0000] {standard_task_runner.py:110} ERROR - Failed to execute job 1859 for task get_send_data_task (HTTPSConnectionPool(host='fake-api-vycpfa6oca-uc.a.run.app', port=443): Max retries exceeded with url: /sales?date=2022-08-11&page=1 (Caused by NameResolutionError("<urllib3.connection.HTTPSConnection object at 0x7f5d7c798ce0>: Failed to resolve 'fake-api-vycpfa6oca-uc.a.run.app' ([Errno -2] Name or service not known)")); 10396)
[2024-05-27T06:54:33.604+0000] {local_task_job_runner.py:240} INFO - Task exited with return code 1
[2024-05-27T06:54:33.630+0000] {taskinstance.py:3498} INFO - 0 downstream tasks scheduled from follow-on schedule check
[2024-05-27T06:54:33.632+0000] {local_task_job_runner.py:222} INFO - ::endgroup::
