[2024-05-26T11:41:36.455+0000] {local_task_job_runner.py:120} INFO - ::group::Pre task execution logs
[2024-05-26T11:41:36.890+0000] {taskinstance.py:2076} INFO - Dependencies all met for dep_context=non-requeueable deps ti=<TaskInstance: process_sales.read_send_data_task scheduled__2023-05-25T01:00:00+00:00 [queued]>
[2024-05-26T11:41:37.038+0000] {taskinstance.py:2076} INFO - Dependencies all met for dep_context=requeueable deps ti=<TaskInstance: process_sales.read_send_data_task scheduled__2023-05-25T01:00:00+00:00 [queued]>
[2024-05-26T11:41:37.049+0000] {taskinstance.py:2306} INFO - Starting attempt 3 of 3
[2024-05-26T11:41:37.315+0000] {taskinstance.py:2330} INFO - Executing <Task(PythonOperator): read_send_data_task> on 2023-05-25 01:00:00+00:00
[2024-05-26T11:41:37.412+0000] {warnings.py:110} WARNING - /home/***/.local/lib/python3.12/site-packages/***/task/task_runner/standard_task_runner.py:61: DeprecationWarning: This process (pid=6326) is multi-threaded, use of fork() may lead to deadlocks in the child.
  pid = os.fork()

[2024-05-26T11:41:37.458+0000] {standard_task_runner.py:63} INFO - Started process 6335 to run task
[2024-05-26T11:41:37.473+0000] {standard_task_runner.py:90} INFO - Running: ['***', 'tasks', 'run', 'process_sales', 'read_send_data_task', 'scheduled__2023-05-25T01:00:00+00:00', '--job-id', '1131', '--raw', '--subdir', 'DAGS_FOLDER/process_sales.py', '--cfg-path', '/tmp/tmpl6x9ewgr']
[2024-05-26T11:41:37.525+0000] {standard_task_runner.py:91} INFO - Job 1131: Subtask read_send_data_task
[2024-05-26T11:41:38.211+0000] {task_command.py:426} INFO - Running <TaskInstance: process_sales.read_send_data_task scheduled__2023-05-25T01:00:00+00:00 [running]> on host 6ecac41592ab
[2024-05-26T11:41:40.372+0000] {taskinstance.py:2648} INFO - Exporting env vars: AIRFLOW_CTX_DAG_EMAIL='gurlenko.1488@gmail.com' AIRFLOW_CTX_DAG_OWNER='***' AIRFLOW_CTX_DAG_ID='process_sales' AIRFLOW_CTX_TASK_ID='read_send_data_task' AIRFLOW_CTX_EXECUTION_DATE='2023-05-25T01:00:00+00:00' AIRFLOW_CTX_TRY_NUMBER='3' AIRFLOW_CTX_DAG_RUN_ID='scheduled__2023-05-25T01:00:00+00:00'
[2024-05-26T11:41:40.405+0000] {taskinstance.py:430} INFO - ::endgroup::
[2024-05-26T11:41:40.414+0000] {taskinstance.py:441} INFO - ::group::Post task execution logs
[2024-05-26T11:41:40.420+0000] {taskinstance.py:2905} ERROR - Task failed with exception
Traceback (most recent call last):
  File "/home/airflow/.local/lib/python3.12/site-packages/airflow/models/taskinstance.py", line 465, in _execute_task
    result = _execute_callable(context=context, **execute_callable_kwargs)
             ^^^^^^^^^^^^^^^^^^^^^^^^^^^^^^^^^^^^^^^^^^^^^^^^^^^^^^^^^^^^^
  File "/home/airflow/.local/lib/python3.12/site-packages/airflow/models/taskinstance.py", line 432, in _execute_callable
    return execute_callable(context=context, **execute_callable_kwargs)
           ^^^^^^^^^^^^^^^^^^^^^^^^^^^^^^^^^^^^^^^^^^^^^^^^^^^^^^^^^^^^
  File "/home/airflow/.local/lib/python3.12/site-packages/airflow/models/baseoperator.py", line 400, in wrapper
    return func(self, *args, **kwargs)
           ^^^^^^^^^^^^^^^^^^^^^^^^^^^
  File "/home/airflow/.local/lib/python3.12/site-packages/airflow/operators/python.py", line 235, in execute
    return_value = self.execute_callable()
                   ^^^^^^^^^^^^^^^^^^^^^^^
  File "/home/airflow/.local/lib/python3.12/site-packages/airflow/operators/python.py", line 252, in execute_callable
    return self.python_callable(*self.op_args, **self.op_kwargs)
           ^^^^^^^^^^^^^^^^^^^^^^^^^^^^^^^^^^^^^^^^^^^^^^^^^^^^^
  File "/opt/airflow/dags/data_sender.py", line 36, in read_send_data
    for json_file in os.listdir(read_dir):
                     ^^^^^^^^^^^^^^^^^^^^
FileNotFoundError: [Errno 2] No such file or directory: '/Users/admin/Desktop/Take data from API/pythonProject/file_storage/raw/sales'
[2024-05-26T11:41:40.563+0000] {taskinstance.py:1206} INFO - Marking task as FAILED. dag_id=process_sales, task_id=read_send_data_task, run_id=scheduled__2023-05-25T01:00:00+00:00, execution_date=20230525T010000, start_date=20240526T114136, end_date=20240526T114140
[2024-05-26T11:41:40.772+0000] {standard_task_runner.py:110} ERROR - Failed to execute job 1131 for task read_send_data_task ([Errno 2] No such file or directory: '/Users/admin/Desktop/Take data from API/pythonProject/file_storage/raw/sales'; 6335)
[2024-05-26T11:41:40.926+0000] {local_task_job_runner.py:240} INFO - Task exited with return code 1
[2024-05-26T11:41:41.109+0000] {taskinstance.py:3498} INFO - 0 downstream tasks scheduled from follow-on schedule check
[2024-05-26T11:41:41.117+0000] {local_task_job_runner.py:222} INFO - ::endgroup::
