[2024-05-25T20:36:21.942+0000] {local_task_job_runner.py:120} INFO - ::group::Pre task execution logs
[2024-05-25T20:36:21.969+0000] {taskinstance.py:2076} INFO - Dependencies all met for dep_context=non-requeueable deps ti=<TaskInstance: process_sales.read_send_data_task manual__2024-05-25T20:35:57.443732+00:00 [queued]>
[2024-05-25T20:36:21.979+0000] {taskinstance.py:2076} INFO - Dependencies all met for dep_context=requeueable deps ti=<TaskInstance: process_sales.read_send_data_task manual__2024-05-25T20:35:57.443732+00:00 [queued]>
[2024-05-25T20:36:21.980+0000] {taskinstance.py:2306} INFO - Starting attempt 2 of 3
[2024-05-25T20:36:21.996+0000] {taskinstance.py:2330} INFO - Executing <Task(PythonOperator): read_send_data_task> on 2024-05-25 20:35:57.443732+00:00
[2024-05-25T20:36:22.005+0000] {warnings.py:110} WARNING - /home/***/.local/lib/python3.12/site-packages/***/task/task_runner/standard_task_runner.py:61: DeprecationWarning: This process (pid=2173) is multi-threaded, use of fork() may lead to deadlocks in the child.
  pid = os.fork()

[2024-05-25T20:36:22.009+0000] {standard_task_runner.py:63} INFO - Started process 2175 to run task
[2024-05-25T20:36:22.010+0000] {standard_task_runner.py:90} INFO - Running: ['***', 'tasks', 'run', 'process_sales', 'read_send_data_task', 'manual__2024-05-25T20:35:57.443732+00:00', '--job-id', '313', '--raw', '--subdir', 'DAGS_FOLDER/process_sales.py', '--cfg-path', '/tmp/tmp4bovxmjt']
[2024-05-25T20:36:22.014+0000] {standard_task_runner.py:91} INFO - Job 313: Subtask read_send_data_task
[2024-05-25T20:36:22.070+0000] {task_command.py:426} INFO - Running <TaskInstance: process_sales.read_send_data_task manual__2024-05-25T20:35:57.443732+00:00 [running]> on host 6ecac41592ab
[2024-05-25T20:36:22.198+0000] {taskinstance.py:2648} INFO - Exporting env vars: AIRFLOW_CTX_DAG_EMAIL='gurlenko.1488@gmail.com' AIRFLOW_CTX_DAG_OWNER='***' AIRFLOW_CTX_DAG_ID='process_sales' AIRFLOW_CTX_TASK_ID='read_send_data_task' AIRFLOW_CTX_EXECUTION_DATE='2024-05-25T20:35:57.443732+00:00' AIRFLOW_CTX_TRY_NUMBER='2' AIRFLOW_CTX_DAG_RUN_ID='manual__2024-05-25T20:35:57.443732+00:00'
[2024-05-25T20:36:22.200+0000] {taskinstance.py:430} INFO - ::endgroup::
[2024-05-25T20:36:22.201+0000] {taskinstance.py:441} INFO - ::group::Post task execution logs
[2024-05-25T20:36:22.202+0000] {taskinstance.py:2905} ERROR - Task failed with exception
Traceback (most recent call last):
  File "/home/airflow/.local/lib/python3.12/site-packages/airflow/models/taskinstance.py", line 465, in _execute_task
    result = _execute_callable(context=context, **execute_callable_kwargs)
             ^^^^^^^^^^^^^^^^^^^^^^^^^^^^^^^^^^^^^^^^^^^^^^^^^^^^^^^^^^^^^
  File "/home/airflow/.local/lib/python3.12/site-packages/airflow/models/taskinstance.py", line 432, in _execute_callable
    return execute_callable(context=context, **execute_callable_kwargs)
           ^^^^^^^^^^^^^^^^^^^^^^^^^^^^^^^^^^^^^^^^^^^^^^^^^^^^^^^^^^^^
  File "/home/airflow/.local/lib/python3.12/site-packages/airflow/models/baseoperator.py", line 400, in wrapper
    return func(self, *args, **kwargs)
           ^^^^^^^^^^^^^^^^^^^^^^^^^^^
  File "/home/airflow/.local/lib/python3.12/site-packages/airflow/operators/python.py", line 235, in execute
    return_value = self.execute_callable()
                   ^^^^^^^^^^^^^^^^^^^^^^^
  File "/home/airflow/.local/lib/python3.12/site-packages/airflow/operators/python.py", line 252, in execute_callable
    return self.python_callable(*self.op_args, **self.op_kwargs)
           ^^^^^^^^^^^^^^^^^^^^^^^^^^^^^^^^^^^^^^^^^^^^^^^^^^^^^
  File "/opt/airflow/dags/data_sender.py", line 36, in read_send_data
    for json_file in os.listdir(read_dir):
                     ^^^^^^^^^^^^^^^^^^^^
FileNotFoundError: [Errno 2] No such file or directory: '/Users/admin/Desktop/Take data from API/pythonProject/file_storage/raw/sales'
[2024-05-25T20:36:22.213+0000] {taskinstance.py:1206} INFO - Marking task as UP_FOR_RETRY. dag_id=process_sales, task_id=read_send_data_task, run_id=manual__2024-05-25T20:35:57.443732+00:00, execution_date=20240525T203557, start_date=20240525T203621, end_date=20240525T203622
[2024-05-25T20:36:22.227+0000] {standard_task_runner.py:110} ERROR - Failed to execute job 313 for task read_send_data_task ([Errno 2] No such file or directory: '/Users/admin/Desktop/Take data from API/pythonProject/file_storage/raw/sales'; 2175)
[2024-05-25T20:36:22.238+0000] {local_task_job_runner.py:240} INFO - Task exited with return code 1
[2024-05-25T20:36:22.258+0000] {taskinstance.py:3498} INFO - 0 downstream tasks scheduled from follow-on schedule check
[2024-05-25T20:36:22.260+0000] {local_task_job_runner.py:222} INFO - ::endgroup::
