[2024-05-27T03:57:57.904+0000] {local_task_job_runner.py:120} INFO - ::group::Pre task execution logs
[2024-05-27T03:57:58.342+0000] {taskinstance.py:2076} INFO - Dependencies all met for dep_context=non-requeueable deps ti=<TaskInstance: process_sales.read_send_data_task scheduled__2023-10-22T01:00:00+00:00 [queued]>
[2024-05-27T03:57:58.474+0000] {taskinstance.py:2076} INFO - Dependencies all met for dep_context=requeueable deps ti=<TaskInstance: process_sales.read_send_data_task scheduled__2023-10-22T01:00:00+00:00 [queued]>
[2024-05-27T03:57:58.483+0000] {taskinstance.py:2306} INFO - Starting attempt 2 of 3
[2024-05-27T03:57:58.764+0000] {taskinstance.py:2330} INFO - Executing <Task(PythonOperator): read_send_data_task> on 2023-10-22 01:00:00+00:00
[2024-05-27T03:57:58.941+0000] {warnings.py:110} WARNING - /home/***/.local/lib/python3.12/site-packages/***/task/task_runner/standard_task_runner.py:61: DeprecationWarning: This process (pid=9691) is multi-threaded, use of fork() may lead to deadlocks in the child.
  pid = os.fork()

[2024-05-27T03:57:59.010+0000] {standard_task_runner.py:63} INFO - Started process 9693 to run task
[2024-05-27T03:57:59.016+0000] {standard_task_runner.py:90} INFO - Running: ['***', 'tasks', 'run', 'process_sales', 'read_send_data_task', 'scheduled__2023-10-22T01:00:00+00:00', '--job-id', '1736', '--raw', '--subdir', 'DAGS_FOLDER/process_sales.py', '--cfg-path', '/tmp/tmpa8vkt_89']
[2024-05-27T03:57:59.141+0000] {standard_task_runner.py:91} INFO - Job 1736: Subtask read_send_data_task
[2024-05-27T03:58:00.090+0000] {task_command.py:426} INFO - Running <TaskInstance: process_sales.read_send_data_task scheduled__2023-10-22T01:00:00+00:00 [running]> on host 6ecac41592ab
[2024-05-27T03:58:02.097+0000] {taskinstance.py:2648} INFO - Exporting env vars: AIRFLOW_CTX_DAG_EMAIL='gurlenko.1488@gmail.com' AIRFLOW_CTX_DAG_OWNER='***' AIRFLOW_CTX_DAG_ID='process_sales' AIRFLOW_CTX_TASK_ID='read_send_data_task' AIRFLOW_CTX_EXECUTION_DATE='2023-10-22T01:00:00+00:00' AIRFLOW_CTX_TRY_NUMBER='2' AIRFLOW_CTX_DAG_RUN_ID='scheduled__2023-10-22T01:00:00+00:00'
[2024-05-27T03:58:02.135+0000] {taskinstance.py:430} INFO - ::endgroup::
[2024-05-27T03:58:02.146+0000] {taskinstance.py:441} INFO - ::group::Post task execution logs
[2024-05-27T03:58:02.156+0000] {taskinstance.py:2905} ERROR - Task failed with exception
Traceback (most recent call last):
  File "/home/airflow/.local/lib/python3.12/site-packages/airflow/models/taskinstance.py", line 465, in _execute_task
    result = _execute_callable(context=context, **execute_callable_kwargs)
             ^^^^^^^^^^^^^^^^^^^^^^^^^^^^^^^^^^^^^^^^^^^^^^^^^^^^^^^^^^^^^
  File "/home/airflow/.local/lib/python3.12/site-packages/airflow/models/taskinstance.py", line 432, in _execute_callable
    return execute_callable(context=context, **execute_callable_kwargs)
           ^^^^^^^^^^^^^^^^^^^^^^^^^^^^^^^^^^^^^^^^^^^^^^^^^^^^^^^^^^^^
  File "/home/airflow/.local/lib/python3.12/site-packages/airflow/models/baseoperator.py", line 400, in wrapper
    return func(self, *args, **kwargs)
           ^^^^^^^^^^^^^^^^^^^^^^^^^^^
  File "/home/airflow/.local/lib/python3.12/site-packages/airflow/operators/python.py", line 235, in execute
    return_value = self.execute_callable()
                   ^^^^^^^^^^^^^^^^^^^^^^^
  File "/home/airflow/.local/lib/python3.12/site-packages/airflow/operators/python.py", line 252, in execute_callable
    return self.python_callable(*self.op_args, **self.op_kwargs)
           ^^^^^^^^^^^^^^^^^^^^^^^^^^^^^^^^^^^^^^^^^^^^^^^^^^^^^
  File "/opt/airflow/dags/data_sender.py", line 36, in read_send_data
    for json_file in os.listdir(read_dir):
                     ^^^^^^^^^^^^^^^^^^^^
FileNotFoundError: [Errno 2] No such file or directory: '/Users/admin/Desktop/Take data from API/pythonProject/file_storage/raw/sales'
[2024-05-27T03:58:02.295+0000] {taskinstance.py:1206} INFO - Marking task as UP_FOR_RETRY. dag_id=process_sales, task_id=read_send_data_task, run_id=scheduled__2023-10-22T01:00:00+00:00, execution_date=20231022T010000, start_date=20240527T035758, end_date=20240527T035802
[2024-05-27T03:58:02.540+0000] {standard_task_runner.py:110} ERROR - Failed to execute job 1736 for task read_send_data_task ([Errno 2] No such file or directory: '/Users/admin/Desktop/Take data from API/pythonProject/file_storage/raw/sales'; 9693)
[2024-05-27T03:58:02.819+0000] {local_task_job_runner.py:240} INFO - Task exited with return code 1
[2024-05-27T03:58:03.204+0000] {taskinstance.py:3498} INFO - 0 downstream tasks scheduled from follow-on schedule check
[2024-05-27T03:58:03.221+0000] {local_task_job_runner.py:222} INFO - ::endgroup::
