[2024-05-26T17:07:07.138+0000] {local_task_job_runner.py:120} INFO - ::group::Pre task execution logs
[2024-05-26T17:07:07.435+0000] {taskinstance.py:2076} INFO - Dependencies all met for dep_context=non-requeueable deps ti=<TaskInstance: process_sales.read_send_data_task scheduled__2023-08-17T01:00:00+00:00 [queued]>
[2024-05-26T17:07:07.515+0000] {taskinstance.py:2076} INFO - Dependencies all met for dep_context=requeueable deps ti=<TaskInstance: process_sales.read_send_data_task scheduled__2023-08-17T01:00:00+00:00 [queued]>
[2024-05-26T17:07:07.525+0000] {taskinstance.py:2306} INFO - Starting attempt 1 of 3
[2024-05-26T17:07:07.713+0000] {taskinstance.py:2330} INFO - Executing <Task(PythonOperator): read_send_data_task> on 2023-08-17 01:00:00+00:00
[2024-05-26T17:07:07.795+0000] {warnings.py:110} WARNING - /home/***/.local/lib/python3.12/site-packages/***/task/task_runner/standard_task_runner.py:61: DeprecationWarning: This process (pid=7985) is multi-threaded, use of fork() may lead to deadlocks in the child.
  pid = os.fork()

[2024-05-26T17:07:07.846+0000] {standard_task_runner.py:63} INFO - Started process 7987 to run task
[2024-05-26T17:07:07.852+0000] {standard_task_runner.py:90} INFO - Running: ['***', 'tasks', 'run', 'process_sales', 'read_send_data_task', 'scheduled__2023-08-17T01:00:00+00:00', '--job-id', '1471', '--raw', '--subdir', 'DAGS_FOLDER/process_sales.py', '--cfg-path', '/tmp/tmprstlck2w']
[2024-05-26T17:07:07.889+0000] {standard_task_runner.py:91} INFO - Job 1471: Subtask read_send_data_task
[2024-05-26T17:07:08.641+0000] {task_command.py:426} INFO - Running <TaskInstance: process_sales.read_send_data_task scheduled__2023-08-17T01:00:00+00:00 [running]> on host 6ecac41592ab
[2024-05-26T17:07:10.383+0000] {taskinstance.py:2648} INFO - Exporting env vars: AIRFLOW_CTX_DAG_EMAIL='gurlenko.1488@gmail.com' AIRFLOW_CTX_DAG_OWNER='***' AIRFLOW_CTX_DAG_ID='process_sales' AIRFLOW_CTX_TASK_ID='read_send_data_task' AIRFLOW_CTX_EXECUTION_DATE='2023-08-17T01:00:00+00:00' AIRFLOW_CTX_TRY_NUMBER='1' AIRFLOW_CTX_DAG_RUN_ID='scheduled__2023-08-17T01:00:00+00:00'
[2024-05-26T17:07:10.421+0000] {taskinstance.py:430} INFO - ::endgroup::
[2024-05-26T17:07:10.433+0000] {taskinstance.py:441} INFO - ::group::Post task execution logs
[2024-05-26T17:07:10.440+0000] {taskinstance.py:2905} ERROR - Task failed with exception
Traceback (most recent call last):
  File "/home/airflow/.local/lib/python3.12/site-packages/airflow/models/taskinstance.py", line 465, in _execute_task
    result = _execute_callable(context=context, **execute_callable_kwargs)
             ^^^^^^^^^^^^^^^^^^^^^^^^^^^^^^^^^^^^^^^^^^^^^^^^^^^^^^^^^^^^^
  File "/home/airflow/.local/lib/python3.12/site-packages/airflow/models/taskinstance.py", line 432, in _execute_callable
    return execute_callable(context=context, **execute_callable_kwargs)
           ^^^^^^^^^^^^^^^^^^^^^^^^^^^^^^^^^^^^^^^^^^^^^^^^^^^^^^^^^^^^
  File "/home/airflow/.local/lib/python3.12/site-packages/airflow/models/baseoperator.py", line 400, in wrapper
    return func(self, *args, **kwargs)
           ^^^^^^^^^^^^^^^^^^^^^^^^^^^
  File "/home/airflow/.local/lib/python3.12/site-packages/airflow/operators/python.py", line 235, in execute
    return_value = self.execute_callable()
                   ^^^^^^^^^^^^^^^^^^^^^^^
  File "/home/airflow/.local/lib/python3.12/site-packages/airflow/operators/python.py", line 252, in execute_callable
    return self.python_callable(*self.op_args, **self.op_kwargs)
           ^^^^^^^^^^^^^^^^^^^^^^^^^^^^^^^^^^^^^^^^^^^^^^^^^^^^^
  File "/opt/airflow/dags/data_sender.py", line 36, in read_send_data
    for json_file in os.listdir(read_dir):
                     ^^^^^^^^^^^^^^^^^^^^
FileNotFoundError: [Errno 2] No such file or directory: '/Users/admin/Desktop/Take data from API/pythonProject/file_storage/raw/sales'
[2024-05-26T17:07:10.609+0000] {taskinstance.py:1206} INFO - Marking task as UP_FOR_RETRY. dag_id=process_sales, task_id=read_send_data_task, run_id=scheduled__2023-08-17T01:00:00+00:00, execution_date=20230817T010000, start_date=20240526T170707, end_date=20240526T170710
[2024-05-26T17:07:11.110+0000] {standard_task_runner.py:110} ERROR - Failed to execute job 1471 for task read_send_data_task ([Errno 2] No such file or directory: '/Users/admin/Desktop/Take data from API/pythonProject/file_storage/raw/sales'; 7987)
[2024-05-26T17:07:11.274+0000] {local_task_job_runner.py:240} INFO - Task exited with return code 1
[2024-05-26T17:07:11.626+0000] {taskinstance.py:3498} INFO - 0 downstream tasks scheduled from follow-on schedule check
[2024-05-26T17:07:11.644+0000] {local_task_job_runner.py:222} INFO - ::endgroup::
