[2024-05-29T18:34:50.330+0000] {task_context_logger.py:104} ERROR - Executor reports task instance <TaskInstance: example_dag_1.python_task_2 manual__2024-05-29T18:23:44.896414+00:00 [queued]> finished (failed) although the task says it's queued. (Info: None) Was the task killed externally?
