[2024-05-26T12:10:46.343+0000] {local_task_job_runner.py:120} INFO - ::group::Pre task execution logs
[2024-05-26T12:10:46.365+0000] {taskinstance.py:2076} INFO - Dependencies all met for dep_context=non-requeueable deps ti=<TaskInstance: process_sales.read_send_data_task scheduled__2023-06-21T01:00:00+00:00 [queued]>
[2024-05-26T12:10:46.373+0000] {taskinstance.py:2076} INFO - Dependencies all met for dep_context=requeueable deps ti=<TaskInstance: process_sales.read_send_data_task scheduled__2023-06-21T01:00:00+00:00 [queued]>
[2024-05-26T12:10:46.373+0000] {taskinstance.py:2306} INFO - Starting attempt 1 of 3
[2024-05-26T12:10:46.387+0000] {taskinstance.py:2330} INFO - Executing <Task(PythonOperator): read_send_data_task> on 2023-06-21 01:00:00+00:00
[2024-05-26T12:10:46.394+0000] {warnings.py:110} WARNING - /home/***/.local/lib/python3.12/site-packages/***/task/task_runner/standard_task_runner.py:61: DeprecationWarning: This process (pid=6784) is multi-threaded, use of fork() may lead to deadlocks in the child.
  pid = os.fork()

[2024-05-26T12:10:46.396+0000] {standard_task_runner.py:63} INFO - Started process 6786 to run task
[2024-05-26T12:10:46.396+0000] {standard_task_runner.py:90} INFO - Running: ['***', 'tasks', 'run', 'process_sales', 'read_send_data_task', 'scheduled__2023-06-21T01:00:00+00:00', '--job-id', '1237', '--raw', '--subdir', 'DAGS_FOLDER/process_sales.py', '--cfg-path', '/tmp/tmp48096v5i']
[2024-05-26T12:10:46.399+0000] {standard_task_runner.py:91} INFO - Job 1237: Subtask read_send_data_task
[2024-05-26T12:10:46.448+0000] {task_command.py:426} INFO - Running <TaskInstance: process_sales.read_send_data_task scheduled__2023-06-21T01:00:00+00:00 [running]> on host 6ecac41592ab
[2024-05-26T12:10:46.594+0000] {taskinstance.py:2648} INFO - Exporting env vars: AIRFLOW_CTX_DAG_EMAIL='gurlenko.1488@gmail.com' AIRFLOW_CTX_DAG_OWNER='***' AIRFLOW_CTX_DAG_ID='process_sales' AIRFLOW_CTX_TASK_ID='read_send_data_task' AIRFLOW_CTX_EXECUTION_DATE='2023-06-21T01:00:00+00:00' AIRFLOW_CTX_TRY_NUMBER='1' AIRFLOW_CTX_DAG_RUN_ID='scheduled__2023-06-21T01:00:00+00:00'
[2024-05-26T12:10:46.596+0000] {taskinstance.py:430} INFO - ::endgroup::
[2024-05-26T12:10:46.597+0000] {taskinstance.py:441} INFO - ::group::Post task execution logs
[2024-05-26T12:10:46.598+0000] {taskinstance.py:2905} ERROR - Task failed with exception
Traceback (most recent call last):
  File "/home/airflow/.local/lib/python3.12/site-packages/airflow/models/taskinstance.py", line 465, in _execute_task
    result = _execute_callable(context=context, **execute_callable_kwargs)
             ^^^^^^^^^^^^^^^^^^^^^^^^^^^^^^^^^^^^^^^^^^^^^^^^^^^^^^^^^^^^^
  File "/home/airflow/.local/lib/python3.12/site-packages/airflow/models/taskinstance.py", line 432, in _execute_callable
    return execute_callable(context=context, **execute_callable_kwargs)
           ^^^^^^^^^^^^^^^^^^^^^^^^^^^^^^^^^^^^^^^^^^^^^^^^^^^^^^^^^^^^
  File "/home/airflow/.local/lib/python3.12/site-packages/airflow/models/baseoperator.py", line 400, in wrapper
    return func(self, *args, **kwargs)
           ^^^^^^^^^^^^^^^^^^^^^^^^^^^
  File "/home/airflow/.local/lib/python3.12/site-packages/airflow/operators/python.py", line 235, in execute
    return_value = self.execute_callable()
                   ^^^^^^^^^^^^^^^^^^^^^^^
  File "/home/airflow/.local/lib/python3.12/site-packages/airflow/operators/python.py", line 252, in execute_callable
    return self.python_callable(*self.op_args, **self.op_kwargs)
           ^^^^^^^^^^^^^^^^^^^^^^^^^^^^^^^^^^^^^^^^^^^^^^^^^^^^^
  File "/opt/airflow/dags/data_sender.py", line 36, in read_send_data
    for json_file in os.listdir(read_dir):
                     ^^^^^^^^^^^^^^^^^^^^
FileNotFoundError: [Errno 2] No such file or directory: '/Users/admin/Desktop/Take data from API/pythonProject/file_storage/raw/sales'
[2024-05-26T12:10:46.608+0000] {taskinstance.py:1206} INFO - Marking task as UP_FOR_RETRY. dag_id=process_sales, task_id=read_send_data_task, run_id=scheduled__2023-06-21T01:00:00+00:00, execution_date=20230621T010000, start_date=20240526T121046, end_date=20240526T121046
[2024-05-26T12:10:46.620+0000] {standard_task_runner.py:110} ERROR - Failed to execute job 1237 for task read_send_data_task ([Errno 2] No such file or directory: '/Users/admin/Desktop/Take data from API/pythonProject/file_storage/raw/sales'; 6786)
[2024-05-26T12:10:46.658+0000] {local_task_job_runner.py:240} INFO - Task exited with return code 1
[2024-05-26T12:10:46.678+0000] {taskinstance.py:3498} INFO - 0 downstream tasks scheduled from follow-on schedule check
[2024-05-26T12:10:46.679+0000] {local_task_job_runner.py:222} INFO - ::endgroup::
