[2024-05-25T20:40:42.915+0000] {local_task_job_runner.py:120} INFO - ::group::Pre task execution logs
[2024-05-25T20:40:42.949+0000] {taskinstance.py:2076} INFO - Dependencies all met for dep_context=non-requeueable deps ti=<TaskInstance: process_sales.read_send_data_task scheduled__2022-11-08T01:00:00+00:00 [queued]>
[2024-05-25T20:40:42.960+0000] {taskinstance.py:2076} INFO - Dependencies all met for dep_context=requeueable deps ti=<TaskInstance: process_sales.read_send_data_task scheduled__2022-11-08T01:00:00+00:00 [queued]>
[2024-05-25T20:40:42.961+0000] {taskinstance.py:2306} INFO - Starting attempt 1 of 3
[2024-05-25T20:40:42.983+0000] {taskinstance.py:2330} INFO - Executing <Task(PythonOperator): read_send_data_task> on 2022-11-08 01:00:00+00:00
[2024-05-25T20:40:42.991+0000] {warnings.py:110} WARNING - /home/***/.local/lib/python3.12/site-packages/***/task/task_runner/standard_task_runner.py:61: DeprecationWarning: This process (pid=2291) is multi-threaded, use of fork() may lead to deadlocks in the child.
  pid = os.fork()

[2024-05-25T20:40:42.994+0000] {standard_task_runner.py:63} INFO - Started process 2293 to run task
[2024-05-25T20:40:42.994+0000] {standard_task_runner.py:90} INFO - Running: ['***', 'tasks', 'run', 'process_sales', 'read_send_data_task', 'scheduled__2022-11-08T01:00:00+00:00', '--job-id', '336', '--raw', '--subdir', 'DAGS_FOLDER/process_sales.py', '--cfg-path', '/tmp/tmpj3clyhez']
[2024-05-25T20:40:42.999+0000] {standard_task_runner.py:91} INFO - Job 336: Subtask read_send_data_task
[2024-05-25T20:40:43.083+0000] {task_command.py:426} INFO - Running <TaskInstance: process_sales.read_send_data_task scheduled__2022-11-08T01:00:00+00:00 [running]> on host 6ecac41592ab
[2024-05-25T20:40:43.206+0000] {taskinstance.py:2648} INFO - Exporting env vars: AIRFLOW_CTX_DAG_EMAIL='gurlenko.1488@gmail.com' AIRFLOW_CTX_DAG_OWNER='***' AIRFLOW_CTX_DAG_ID='process_sales' AIRFLOW_CTX_TASK_ID='read_send_data_task' AIRFLOW_CTX_EXECUTION_DATE='2022-11-08T01:00:00+00:00' AIRFLOW_CTX_TRY_NUMBER='1' AIRFLOW_CTX_DAG_RUN_ID='scheduled__2022-11-08T01:00:00+00:00'
[2024-05-25T20:40:43.210+0000] {taskinstance.py:430} INFO - ::endgroup::
[2024-05-25T20:40:43.211+0000] {taskinstance.py:441} INFO - ::group::Post task execution logs
[2024-05-25T20:40:43.212+0000] {taskinstance.py:2905} ERROR - Task failed with exception
Traceback (most recent call last):
  File "/home/airflow/.local/lib/python3.12/site-packages/airflow/models/taskinstance.py", line 465, in _execute_task
    result = _execute_callable(context=context, **execute_callable_kwargs)
             ^^^^^^^^^^^^^^^^^^^^^^^^^^^^^^^^^^^^^^^^^^^^^^^^^^^^^^^^^^^^^
  File "/home/airflow/.local/lib/python3.12/site-packages/airflow/models/taskinstance.py", line 432, in _execute_callable
    return execute_callable(context=context, **execute_callable_kwargs)
           ^^^^^^^^^^^^^^^^^^^^^^^^^^^^^^^^^^^^^^^^^^^^^^^^^^^^^^^^^^^^
  File "/home/airflow/.local/lib/python3.12/site-packages/airflow/models/baseoperator.py", line 400, in wrapper
    return func(self, *args, **kwargs)
           ^^^^^^^^^^^^^^^^^^^^^^^^^^^
  File "/home/airflow/.local/lib/python3.12/site-packages/airflow/operators/python.py", line 235, in execute
    return_value = self.execute_callable()
                   ^^^^^^^^^^^^^^^^^^^^^^^
  File "/home/airflow/.local/lib/python3.12/site-packages/airflow/operators/python.py", line 252, in execute_callable
    return self.python_callable(*self.op_args, **self.op_kwargs)
           ^^^^^^^^^^^^^^^^^^^^^^^^^^^^^^^^^^^^^^^^^^^^^^^^^^^^^
  File "/opt/airflow/dags/data_sender.py", line 36, in read_send_data
    for json_file in os.listdir(read_dir):
                     ^^^^^^^^^^^^^^^^^^^^
FileNotFoundError: [Errno 2] No such file or directory: '/Users/admin/Desktop/Take data from API/pythonProject/file_storage/raw/sales'
[2024-05-25T20:40:43.223+0000] {taskinstance.py:1206} INFO - Marking task as UP_FOR_RETRY. dag_id=process_sales, task_id=read_send_data_task, run_id=scheduled__2022-11-08T01:00:00+00:00, execution_date=20221108T010000, start_date=20240525T204042, end_date=20240525T204043
[2024-05-25T20:40:43.237+0000] {standard_task_runner.py:110} ERROR - Failed to execute job 336 for task read_send_data_task ([Errno 2] No such file or directory: '/Users/admin/Desktop/Take data from API/pythonProject/file_storage/raw/sales'; 2293)
[2024-05-25T20:40:43.267+0000] {local_task_job_runner.py:240} INFO - Task exited with return code 1
[2024-05-25T20:40:43.286+0000] {taskinstance.py:3498} INFO - 0 downstream tasks scheduled from follow-on schedule check
[2024-05-25T20:40:43.288+0000] {local_task_job_runner.py:222} INFO - ::endgroup::
